Workbook
Name Country: OFFSET(List!$C$2,0,0,COUNTA(List!$C:$C)-1,1)
Name StudentHomeFaculty: OFFSET(List!$A$2,0,0,COUNTA(List!$A:$A)-1,1)
Name University: OFFSET(List!$D$2,0,0,COUNTA(List!$D:$D)-1,1)
Name UwideFaculty: OFFSET(List!$B$2,0,0,COUNTA(List!$B:$B)-1,1)

Sheet Calculator
A1: #VALUE! | F1: updated as of 12 December 2025
B2: SEP Credit Transfer Calculator (for outgoing students from AY2026/27 onwards)
B3: Use this calculator to estimate the NUS unit equivalent of your Partner University (PU) courses and plan your semester workload.
B4: Important: This tool is for guidance only. Final course mappings are subject to approval from the respective faculties. Depending on the Faculty, students may transfer a maximum of 20 - 24 NUS units for semester-long SEPs (excluding summer and winter programmes); please check with your faculty SEP coordinator for the exact number.
B6: Step 1. Select your Home Faculty
B7: Step 2. Select whether you wish to embark on a University-wide or Faculty-level SEP
B8: Step 3. Select country of PU
B9: Step 4. Select the PU
B10: Step 5. Key in the PU Course Credits for each course you wish to take at the PU and view the NUS Equivalent Units in SEP Credit Transfer Conversion Table
B11: Step 6. View the total workload at the PU and the NUS equivalent in cell F30 and G30, respectively. Do take note of any limit the PU may impose on the total number of courses exchange students can take.
B12: Step 7 (optional). Key in any additional courses and their corresponding credits in cells E25 - E29 and F25 - F29 if you plan to take more than 5 courses.
B13: To select another PU, remove all entries from Steps 1 to 5 and start over.
B14: Note: If the PU you are interested in is not listed, please contact your faculty SEP coordinator
... B17: FAQ on the calculator
A19: Step 1 | B19: Student's Home Faculty
A20: Step 2 | B20: U-wide/Faculty
A21: Step 3 | B21: Country
A22: Step 4 | B22: Partner University Name
A25: SEP Credit Transfer Conversion Table
A26: PU Course | B26: PU Course Credits for Transfer | C26: NUS Equivalent Units (Rounded Up) | E26: How do I use the calculator to plan my semester workload at a partner university?
A27: Course 1 | C27: {=IF( OR($C$20="", $C$21="", $C$22=""), "", IFERROR( CEILING( B27 * INDEX('Credit Scores'!$G:$G, MATCH(1, ('Credit Scores'!$B:$B=Calculator!$C$20)* ('Credit Scores'!$C:$C=Calculator!$C$21)* ('Credit Scores'!$D:$D=Calculator!$C$22), 0) ), 1 ), "Please contact GRO" ) )} | E27: Let’s use the normal semester workload of 20 NUS units as an example.
A28: Course 2 | C28: {=IF( OR($C$20="", $C$21="", $C$22=""), "", IFERROR( CEILING( B28 * INDEX('Credit Scores'!$G:$G, MATCH(1, ('Credit Scores'!$B:$B=Calculator!$C$20)* ('Credit Scores'!$C:$C=Calculator!$C$21)* ('Credit Scores'!$D:$D=Calculator!$C$22), 0) ), 1 ), "Please contact GRO" ) )} | E28: Add up the NUS equivalent units for each course you plan to transfer.
A29: Course 3 | C29: {=IF( OR($C$20="", $C$21="", $C$22=""), "", IFERROR( CEILING( B29 * INDEX('Credit Scores'!$G:$G, MATCH(1, ('Credit Scores'!$B:$B=Calculator!$C$20)* ('Credit Scores'!$C:$C=Calculator!$C$21)* ('Credit Scores'!$D:$D=Calculator!$C$22), 0) ), 1 ), "Please contact GRO" ) )} | E29: E.g., if you plan to take the following five courses at Purdue University:
A30: Course 4 | C30: {=IF( OR($C$20="", $C$21="", $C$22=""), "", IFERROR( CEILING( B30 * INDEX('Credit Scores'!$G:$G, MATCH(1, ('Credit Scores'!$B:$B=Calculator!$C$20)* ('Credit Scores'!$C:$C=Calculator!$C$21)* ('Credit Scores'!$D:$D=Calculator!$C$22), 0) ), 1 ), "Please contact GRO" ) )}
A31: Course 5 | C31: {=IF( OR($C$20="", $C$21="", $C$22=""), "", IFERROR( CEILING( B31 * INDEX('Credit Scores'!$G:$G, MATCH(1, ('Credit Scores'!$B:$B=Calculator!$C$20)* ('Credit Scores'!$C:$C=Calculator!$C$21)* ('Credit Scores'!$D:$D=Calculator!$C$22), 0) ), 1 ), "Please contact GRO" ) )} | E31: SEP Credit Transfer Conversion Table
C32: {=IF( OR($C$20="", $C$21="", $C$22=""), "", IFERROR( CEILING( B32 * INDEX('Credit Scores'!$G:$G, MATCH(1, ('Credit Scores'!$B:$B=Calculator!$C$20)* ('Credit Scores'!$C:$C=Calculator!$C$21)* ('Credit Scores'!$D:$D=Calculator!$C$22), 0) ), 1 ), "Please contact GRO" ) )} | E32: PU Course | F32: PU Course Credits for Transfer | G32: NUS Equivalent Units (Rounded Up)
C33: {=IF( OR($C$20="", $C$21="", $C$22=""), "", IFERROR( CEILING( B33 * INDEX('Credit Scores'!$G:$G, MATCH(1, ('Credit Scores'!$B:$B=Calculator!$C$20)* ('Credit Scores'!$C:$C=Calculator!$C$21)* ('Credit Scores'!$D:$D=Calculator!$C$22), 0) ), 1 ), "Please contact GRO" ) )} | E33: Course 1 | F33: 2 | G33: 3
C34: {=IF( OR($C$20="", $C$21="", $C$22=""), "", IFERROR( CEILING( B34 * INDEX('Credit Scores'!$G:$G, MATCH(1, ('Credit Scores'!$B:$B=Calculator!$C$20)* ('Credit Scores'!$C:$C=Calculator!$C$21)* ('Credit Scores'!$D:$D=Calculator!$C$22), 0) ), 1 ), "Please contact GRO" ) )} | E34: Course 2 | F34: 3 | G34: 4
C35: {=IF( OR($C$20="", $C$21="", $C$22=""), "", IFERROR( CEILING( B35 * INDEX('Credit Scores'!$G:$G, MATCH(1, ('Credit Scores'!$B:$B=Calculator!$C$20)* ('Credit Scores'!$C:$C=Calculator!$C$21)* ('Credit Scores'!$D:$D=Calculator!$C$22), 0) ), 1 ), "Please contact GRO" ) )} | E35: Course 3 | F35: 3 | G35: 4
C36: {=IF( OR($C$20="", $C$21="", $C$22=""), "", IFERROR( CEILING( B36 * INDEX('Credit Scores'!$G:$G, MATCH(1, ('Credit Scores'!$B:$B=Calculator!$C$20)* ('Credit Scores'!$C:$C=Calculator!$C$21)* ('Credit Scores'!$D:$D=Calculator!$C$22), 0) ), 1 ), "Please contact GRO" ) )} | E36: Course 4 | F36: 2 | G36: 3
A37: Total No. of Units | B37: =SUM(B27:B36) -> 0 | C37: =SUM(C27:C36) -> 0 | E37: Course 5 | F37: 4 | G37: 6
E38: Total No. of Units | F38: =SUM(F33:F37) -> 14 | G38: =SUM(G33:G37) -> 20

Sheet Credit Scores
A1: Region | B1: U-wide/ Faculty | C1: Country | D1: University Name | E1: Regular semester workload for full-time undergraduate students | F1: Units | G1: Conversion | H1: Remarks
A2: Americas | B2: BIZ | C2: Brazil | D2: FGV EAESP - Fundação Getulio Vargas São Paulo School of Business Administration | E2: 28 | F2: FGV credits | G2: =20/E2 -> 0.71428571 | H2: No Change by BIZ
A3: Americas | B3: CDE | C3: Brazil | D3: University of Sao Paulo | E3: 20 | F3: credits | G3: =20/E3 -> 1 | H3: GRO's Info tallies with PVO's search
A4: Americas | B4: U-wide | C4: Canada | D4: Concordia University | E4: 15 | F4: credits | G4: =20/E4 -> 1.3333333 | H4: GRO Info & FASS website Tallies
A5: Americas | B5: U-wide | C5: Canada | D5: Dalhousie University | E5: 15 | F5: credit hours | G5: =20/E5 -> 1.3333333 | H5: GRO Info & FASS website Tallies
A6: Americas | B6: BIZ | C6: Canada | D6: HEC Montréal | E6: 15 | F6: units | G6: =20/E6 -> 1.3333333 | H6: GRO Info - Verified by PVO
A7: Americas | B7: U-wide | C7: Canada | D7: McGill University | E7: 15 | F7: credits | G7: =20/E7 -> 1.3333333 | H7: GRO Info & FASS website Tallies
A8: Americas | B8: U-wide | C8: Canada | D8: McMaster University | E8: 15 | F8: units | G8: =20/E8 -> 1.3333333 | H8: GRO Info - Verified by PVO
A9: Americas | B9: U-wide | C9: Canada | D9: Queen’s University at Kingston | E9: 15 | F9: units | G9: =20/E9 -> 1.3333333 | H9: GRO Info & FASS website Tallies
A10: Americas | B10: BIZ | C10: Canada | D10: Queen's University Smith School of Business | E10: 15 | F10: Queen’s units | G10: =20/E10 -> 1.3333333 | H10: GRO Info & FASS website Tallies
A11: Americas | B11: U-wide | C11: Canada | D11: Simon Fraser University | E11: 15 | F11: units | G11: =20/E11 -> 1.3333333 | H11: GRO Info & FASS website Tallies
A12: Americas | B12: U-wide | C12: Canada | D12: University of Alberta | E12: 15 | F12: credits | G12: =20/E12 -> 1.3333333 | H12: GRO Info & FASS website Tallies
A13: Americas | B13: U-wide | C13: Canada | D13: University of British Columbia | E13: 15 | F13: credits | G13: =20/E13 -> 1.3333333 | H13: GRO Info & FASS website Tallies
... A47: Americas | B47: U-wide | C47: USA | D47: Northwestern University (quarter exchange) | E47: 5.625 | F47: credits | G47: =20/E47 -> 3.5555556 | H47: Verified by PVO
A48: Americas | B48: CDE | C48: USA | D48: Ohio State University | E48: 15 | F48: credits | G48: =20/Table1[[#This Row],[Regular semester workload for full-time undergraduate students]] -> 1.3333333 | H48: Provided by CDE to PVO
A49: Americas | B49: U-wide | C49: USA | D49: Pennsylvania State University | E49: 15 | F49: credits | G49: =20/E49 -> 1.3333333 | H49: GRO Info & FASS website Tallies
A50: Americas | B50: U-wide | C50: USA | D50: Princeton University | E50: 4 | F50: courses | G50: =20/E50 -> 5 | H50: GRO Info & FASS website Tallies
A51: Americas | B51: U-wide | C51: USA | D51: Purdue University | E51: 15 | F51: credits | G51: =20/E51 -> 1.3333333 | H51: GRO Info & FASS website Tallies
A52: Americas | B52: U-wide | C52: USA | D52: Rice University | E52: 15 | F52: credits | G52: =20/E52 -> 1.3333333 | H52: GRO Info & FASS website Tallies
A53: Americas | B53: NUSC | C53: USA | D53: Smith College | E53: 16 | F53: credits | G53: =20/E53 -> 1.25 | H53: GRO Info - Verified by PVO
A54: Americas | B54: U-wide | C54: USA | D54: Texas A&M University | E54: 15 | F54: credits | G54: =20/E54 -> 1.3333333 | H54: GRO Info & FASS website Tallies
A55: Americas | B55: U-wide | C55: USA | D55: Tulane University | E55: 15 | F55: credits | G55: =20/E55 -> 1.3333333 | H55: GRO Info & FASS website Tallies
A56: Americas | B56: BIZ | C56: USA | D56: Tulane University School of Business | E56: 15 | F56: credits | G56: =20/E56 -> 1.3333333 | H56: GRO Info & FASS website Tallies
A57: Americas | B57: U-wide | C57: USA | D57: University of Alaska Fairbanks | E57: 15 | F57: credits | G57: =20/E57 -> 1.3333333 | H57: GRO Info & FASS website Tallies
A58: Americas | B58: U-wide | C58: USA | D58: University of Arizona | E58: 15 | F58: credits | G58: =20/E58 -> 1.3333333 | H58: GRO Info & FASS website Tallies
A59: Americas | B59: U-wide | C59: USA | D59: University of California, Berkeley & Merced (semester exchange) | E59: 15 | F59: units | G59: =20/E59 -> 1.3333333 | H59: GRO Info & FASS website Tallies
A60: Americas | B60: U-wide | C60: USA | D60: University of California, except Berkeley & Merced (quarter exchange) | E60: 22.5 | F60: units | G60: =20/E60 -> 0.88888889 | H60: GRO Info & FASS website Tallies
... A91: Asia & Australasia | B91: U-wide | C91: Australia | D91: Australian National University | E91: 24 | F91: units | G91: =20/E91 -> 0.83333333 | H91: GRO Info & FASS website Tallies
A92: Asia & Australasia | B92: BIZ | C92: Australia | D92: Australian National University | E92: 24 | F92: units | G92: 0.83333333 | H92: GRO Info & FASS website Tallies
A93: Asia & Australasia | B93: FoS | C93: Australia | D93: La Trobe University | E93: 60 | F93: credits | G93: =20/E93 -> 0.33333333 | H93: GRO Info - Verified by PVO
A94: Asia & Australasia | B94: U-wide | C94: Australia | D94: Monash University | E94: 24 | F94: credits | G94: =20/E94 -> 0.83333333 | H94: GRO Info & FASS website Tallies
A95: Asia & Australasia | B95: BIZ | C95: Australia | D95: Monash University | E95: 24 | F95: credits | G95: 0.83333333 | H95: GRO Info & FASS website Tallies
A96: Asia & Australasia | B96: BIZ | C96: Australia | D96: Queensland University of Technology | E96: 48 | F96: QUT Credit Points | G96: =20/E96 -> 0.41666667 | H96: No Change by BIZ
A97: Asia & Australasia | B97: U-wide | C97: Australia | D97: Adelaide University | E97: 24 | F97: units | G97: =20/E97 -> 0.83333333 | H97: GRO Info - Verified by PVO
A98: Asia & Australasia | B98: U-wide | C98: Australia | D98: University of Melbourne | E98: 50 | F98: points | G98: =20/E98 -> 0.4 | H98: GRO Info & FASS website Tallies
A99: Asia & Australasia | B99: BIZ | C99: Australia | D99: University of Melbourne | E99: 50 | F99: points | G99: 0.4 | H99: GRO Info & FASS website Tallies
A100: Asia & Australasia | B100: FoS | C100: Australia | D100: University of Newcastle | E100: 40 | F100: units | G100: =20/E100 -> 0.5 | H100: GRO Info - Verified by PVO
A101: Asia & Australasia | B101: U-wide | C101: Australia | D101: University of Queensland | E101: 8 | F101: units | G101: =20/E101 -> 2.5 | H101: GRO Info & FASS website Tallies
A102: Asia & Australasia | B102: U-wide | C102: Australia | D102: University of Sydney | E102: 24 | F102: cp | G102: =20/E102 -> 0.83333333 | H102: GRO Info & FASS website Tallies
A103: Asia & Australasia | B103: U-wide | C103: Australia | D103: University of Western Australia | E103: 24 | F103: credits | G103: =20/E103 -> 0.83333333 | H103: GRO Info & FASS website Tallies
...

Sheet List
A1: Student's Home Faculty | B1: U-wide/Faculty | C1: Country | D1: University Name
A2: BIZ | B2: {=IF(Calculator!C19="", "", _xlfn._xlws.SORT(_xlfn.UNIQUE(_xlfn._xlws.FILTER('Credit Scores'!B2:B367, (('Credit Scores'!B2:B367=Calculator!C19) + ('Credit Scores'!B2:B367="U-wide")) * ((Calculator!C21="") + ('Credit Scores'!C2:C367=Calculator!C21)) * ((Calculator!C22="") + ('Credit Scores'!D2:D367=Calculator!C22)) ))))} | C2: {=IF(Calculator!C19="", "", _xlfn._xlws.SORT(_xlfn.UNIQUE(_xlfn._xlws.FILTER('Credit Scores'!C2:C367, ((Calculator!C20="") + ('Credit Scores'!B2:B367=Calculator!C20)) * ((Calculator!C22="") + ('Credit Scores'!D2:D367=Calculator!C22)) ))))} | D2: {=IF(Calculator!C19="", "", _xlfn._xlws.SORT(_xlfn.UNIQUE(_xlfn._xlws.FILTER('Credit Scores'!D2:D367, ((Calculator!C20="") + ('Credit Scores'!B2:B367=Calculator!C20)) * ((Calculator!C21="") + ('Credit Scores'!C2:C367=Calculator!C21)) ))))}
A3: CDE
A4: FASS
A5: FoS
A6: NUSC
A7: SoC
